<?xml version="1.0" encoding="utf-8"?>
<!-- This URDF was automatically created by SolidWorks to URDF Exporter! Originally created by Stephen Brawner (brawner@gmail.com) 
     Commit Version: 1.6.0-4-g7f85cfe  Build Version: 1.6.7995.38578
     For more information, please see http://wiki.ros.org/sw_urdf_exporter -->
<robot
  name="URDF">
  <link
    name="base_link">
    <inertial>
      <origin
        xyz="8.6615E-05 4.8062E-05 0.0090486"
        rpy="0 0 0" />
      <mass
        value="4.3537" />
      <inertia
        ixx="0.013527"
        ixy="3.1301E-07"
        ixz="-2.8306E-06"
        iyy="0.013524"
        iyz="3.4906E-06"
        izz="0.026698" />
    </inertial>
    <visual>
      <origin
        xyz="0 0 0"
        rpy="0 0 0" />
      <geometry>
        <mesh
          filename="package://URDF/meshes/base_link.STL" />
      </geometry>
      <material
        name="">
        <color
          rgba="0.65098 0.61961 0.58824 1" />
      </material>
    </visual>
    <collision>
      <origin
        xyz="0 0 0"
        rpy="0 0 0" />
      <geometry>
        <mesh
          filename="package://URDF/meshes/base_link.STL" />
      </geometry>
    </collision>
  </link>
  <link
    name="link1">
    <inertial>
      <origin
        xyz="-0.00012189 0.0022278 0.028806"
        rpy="0 0 0" />
      <mass
        value="0.86168" />
      <inertia
        ixx="0.00020738"
        ixy="-1.9958E-06"
        ixz="2.338E-07"
        iyy="0.00020881"
        iyz="-8.8008E-06"
        izz="0.00031571" />
    </inertial>
    <visual>
      <origin
        xyz="0 0 0"
        rpy="0 0 0" />
      <geometry>
        <mesh
          filename="package://URDF/meshes/link1.STL" />
      </geometry>
      <material
        name="">
        <color
          rgba="0.89804 0.91765 0.92941 1" />
      </material>
    </visual>
    <collision>
      <origin
        xyz="0 0 0"
        rpy="0 0 0" />
      <geometry>
        <mesh
          filename="package://URDF/meshes/link1.STL" />
      </geometry>
    </collision>
  </link>
  <joint
    name="joint1"
    type="revolute">
    <origin
      xyz="0 0 0.068"
      rpy="0 0 0" />
    <parent
      link="base_link" />
    <child
      link="link1" />
    <axis
      xyz="0 0 1" />
    <limit
      lower="-3.14"
      upper="3.14"
      effort="16"
      velocity="1" />
  </joint>
  <link
    name="link2">
    <inertial>
      <origin
        xyz="-0.00010161 0.02846 0.14834"
        rpy="0 0 0" />
      <mass
        value="1.8959" />
      <inertia
        ixx="0.00097332"
        ixy="7.1635E-07"
        ixz="3.9823E-06"
        iyy="0.0011899"
        iyz="4.1959E-07"
        izz="0.00050598" />
    </inertial>
    <visual>
      <origin
        xyz="0 0 0"
        rpy="0 0 0" />
      <geometry>
        <mesh
          filename="package://URDF/meshes/link2.STL" />
      </geometry>
      <material
        name="">
        <color
          rgba="0.64706 0.61961 0.58824 1" />
      </material>
    </visual>
    <collision>
      <origin
        xyz="0 0 0"
        rpy="0 0 0" />
      <geometry>
        <mesh
          filename="package://URDF/meshes/link2.STL" />
      </geometry>
    </collision>
  </link>
  <joint
    name="joint2"
    type="revolute">
    <origin
      xyz="-9.827E-05 0.03645 0.025"
      rpy="0 0 0.002696" />
    <parent
      link="link1" />
    <child
      link="link2" />
    <axis
      xyz="0 -1 0" />
    <limit
      lower="-3.14"
      upper="3.14"
      effort="16"
      velocity="1" />
  </joint>
  <link
    name="link3">
    <inertial>
      <origin
        xyz="-5.5451E-05 -0.022085 0.16084"
        rpy="0 0 0" />
      <mass
        value="0.50538" />
      <inertia
        ixx="0.0012084"
        ixy="-2.9159E-07"
        ixz="3.8584E-07"
        iyy="0.0012781"
        iyz="6.9006E-08"
        izz="0.00010693" />
    </inertial>
    <visual>
      <origin
        xyz="0 0 0"
        rpy="0 0 0" />
      <geometry>
        <mesh
          filename="package://URDF/meshes/link3.STL" />
      </geometry>
      <material
        name="">
        <color
          rgba="1 1 1 1" />
      </material>
    </visual>
    <collision>
      <origin
        xyz="0 0 0"
        rpy="0 0 0" />
      <geometry>
        <mesh
          filename="package://URDF/meshes/link3.STL" />
      </geometry>
    </collision>
  </link>
  <joint
    name="joint3"
    type="revolute">
    <origin
      xyz="-6.7401E-05 0 0.2969"
      rpy="0 0 -0.002696" />
    <parent
      link="link2" />
    <child
      link="link3" />
    <axis
      xyz="0 1 0" />
    <limit
      lower="-3.14"
      upper="3.14"
      effort="16"
      velocity="1" />
  </joint>
  <link
    name="link4">
    <inertial>
      <origin
        xyz="2.3585E-05 0.030308 0.0024543"
        rpy="0 0 0" />
      <mass
        value="0.33939" />
      <inertia
        ixx="7.3684E-05"
        ixy="6.1914E-07"
        ixz="4.4215E-08"
        iyy="7.4871E-05"
        iyz="-2.6763E-06"
        izz="0.00010261" />
    </inertial>
    <visual>
      <origin
        xyz="0 0 0"
        rpy="0 0 0" />
      <geometry>
        <mesh
          filename="package://URDF/meshes/link4.STL" />
      </geometry>
      <material
        name="">
        <color
          rgba="0.89804 0.91765 0.92941 1" />
      </material>
    </visual>
    <collision>
      <origin
        xyz="0 0 0"
        rpy="0 0 0" />
      <geometry>
        <mesh
          filename="package://URDF/meshes/link4.STL" />
      </geometry>
    </collision>
  </link>
  <joint
    name="joint4"
    type="revolute">
    <origin
      xyz="0 -0.008 0.23"
      rpy="0 0 0" />
    <parent
      link="link3" />
    <child
      link="link4" />
    <axis
      xyz="0 1 0" />
    <limit
      lower="-3.14"
      upper="3.14"
      effort="6"
      velocity="2" />
  </joint>
  <link
    name="link5">
    <inertial>
      <origin
        xyz="0.0024543 2.3588E-05 0.035308"
        rpy="0 0 0" />
      <mass
        value="0.33939" />
      <inertia
        ixx="0.00010261"
        ixy="4.5417E-08"
        ixz="-2.6763E-06"
        iyy="7.3686E-05"
        iyz="6.1913E-07"
        izz="7.4871E-05" />
    </inertial>
    <visual>
      <origin
        xyz="0 0 0"
        rpy="0 0 0" />
      <geometry>
        <mesh
          filename="package://URDF/meshes/link5.STL" />
      </geometry>
      <material
        name="">
        <color
          rgba="0.89804 0.91765 0.92941 1" />
      </material>
    </visual>
    <collision>
      <origin
        xyz="0 0 0"
        rpy="0 0 0" />
      <geometry>
        <mesh
          filename="package://URDF/meshes/link5.STL" />
      </geometry>
    </collision>
  </link>
  <joint
    name="joint5"
    type="revolute">
    <origin
      xyz="0 0.033201 0.0205"
      rpy="0 0 0" />
    <parent
      link="link4" />
    <child
      link="link5" />
    <axis
      xyz="0 0 1" />
    <limit
      lower="-3.14"
      upper="3.14"
      effort="6"
      velocity="2" />
  </joint>
  <link
    name="link6">
    <inertial>
      <origin
        xyz="0.038711 -0.00017028 0.0075993"
        rpy="0 0 0" />
      <mass
        value="0.53794" />
      <inertia
        ixx="0.00024196"
        ixy="-2.0687E-07"
        ixz="1.8008E-07"
        iyy="0.00010253"
        iyz="-1.0575E-06"
        izz="0.000198" />
    </inertial>
    <visual>
      <origin
        xyz="0 0 0"
        rpy="0 0 0" />
      <geometry>
        <mesh
          filename="package://URDF/meshes/link6.STL" />
      </geometry>
      <material
        name="">
        <color
          rgba="0.93725 0.93725 0.93725 0.4" />
      </material>
    </visual>
    <collision>
      <origin
        xyz="0 0 0"
        rpy="0 0 0" />
      <geometry>
        <mesh
          filename="package://URDF/meshes/link6.STL" />
      </geometry>
    </collision>
  </link>
  <joint
    name="joint6"
    type="revolute">
    <origin
      xyz="0.0205 0 0.038201"
      rpy="0 0 0" />
    <parent
      link="link5" />
    <child
      link="link6" />
    <axis
      xyz="1 0 0" />
    <limit
      lower="-3.14"
      upper="3.14"
      effort="6"
      velocity="2" />
  </joint>
</robot>